#VRML_SIM R2021a utf8
WorldInfo {
  coordinateSystem "NUE"
}
Viewpoint {
  orientation -0.08830996043938039 0.9953120562847045 -0.03943680389570287 5.4396807682769746
  position -0.41578635475223175 0.03560008755681092 -0.14912218511680836
}
TexturedBackground {
}
TexturedBackgroundLight {
}
RectangleArena {
  floorSize 5 5
  floorAppearance Parquetry {
    type "dark strip"
    colorOverride 0 0 0
  }
}
Robot {
  translation -0.21959064068908424 0.02981908725538198 -0.4411409901601824
  rotation -0.33729918923286595 -0.9339346313074153 0.11830199232275686 -0.718729730428316
  children [
    DEF rightArm HingeJoint {
      jointParameters HingeJointParameters {
        position 55.166837618287644
        anchor -0.062 0.00787729 0.10054
      }
      device [
        RotationalMotor {
          name "rightArmMotor"
        }
        PositionSensor {
          name "rightArmEncoder"
        }
      ]
      endPoint Solid {
        translation -0.07400000003737509 0.012117316724377467 0.09537693601450896
        rotation -0.9999999999999115 -5.7384540133106794e-08 4.1689645033258756e-07 1.4225780513701756
        children [
          DEF leftArm Group {
            children [
              Transform {
                translation 0.0197 0 0.04
                children [
                  Shape {
                    appearance PBRAppearance {
                      baseColor 0 1 0
                      roughness 1
                      metalness 0
                    }
                    geometry Box {
                      size 0.04 0.005 0.005
                    }
                  }
                ]
              }
              Transform {
                translation -0.003 0 0.02
                children [
                  Shape {
                    appearance PBRAppearance {
                      baseColor 1 0 0
                      roughness 1
                      metalness 0
                    }
                    geometry Box {
                      size 0.005 0.005 0.045
                    }
                  }
                ]
              }
            ]
          }
        ]
        name "solid(5)"
        boundingObject USE leftArm
        physics Physics {
        }
        linearVelocity 0.04128049712842993 -0.012598651819899024 0.05158638773608627
        angularVelocity 1.561437921100584 5.487631374730986e-05 -1.249489323639703
      }
    }
    DEF leftArm HingeJoint {
      jointParameters HingeJointParameters {
        anchor 0.01 0.1 0.01
      }
      device [
        PositionSensor {
          name "leftArmEncoder"
        }
        RotationalMotor {
          name "leftArmMotor"
        }
      ]
    }
    Camera {
      translation 0 0.05 0.09
      rotation 0.00010394198776057495 -0.9914448832549232 -0.13052598463024384 -3.140015307179586
      children [
        Shape {
          appearance PBRAppearance {
            roughness 1
            metalness 0
          }
          geometry Cylinder {
            height 0.01
            radius 0.005
          }
        }
      ]
      name "cam"
      width 128
      height 128
    }
    Display {
      children [
        Shape {
          appearance Appearance {
            material Material {
              emissiveColor 1 1 1
            }
            texture ImageTexture {
              filtering 0
            }
          }
        }
      ]
      width 128
      height 128
    }
    Solid {
      children [
        DEF basePlate Group {
          children [
            DEF rightServo Transform {
              translation -0.06 0.0075 0.1
              children [
                Shape {
                  appearance PBRAppearance {
                    baseColor 0 0 0
                    roughness 1
                    metalness 0
                  }
                  geometry Box {
                    size 0.02 0.01 0.01
                  }
                }
              ]
            }
            DEF leftServo Transform {
              translation 0.06 0.0075 0.1
              children [
                Shape {
                  appearance PBRAppearance {
                    baseColor 0 0 0
                    roughness 1
                    metalness 0
                  }
                  geometry Box {
                    size 0.02 0.01 0.01
                  }
                }
              ]
            }
            Transform {
              translation 0 0 0.005
              children [
                Shape {
                  appearance PBRAppearance {
                    baseColor 0 0 1
                    roughness 1
                    metalness 0
                  }
                  geometry Box {
                    size 0.08 0.005 0.07
                  }
                }
              ]
            }
            Transform {
              translation 0 0 0.075
              children [
                Shape {
                  appearance PBRAppearance {
                    baseColor 0 1 1
                    roughness 1
                    metalness 0
                  }
                  geometry Box {
                    size 0.14 0.005 0.07
                  }
                }
              ]
            }
          ]
        }
      ]
      name "solid(4)"
      boundingObject USE basePlate
    }
    DEF jointLeft HingeJoint {
      jointParameters HingeJointParameters {
        position -1.1173371998658845e-08
        anchor 0.057 0 0
      }
      device [
        RotationalMotor {
          name "motorLeft"
        }
      ]
      endPoint Solid {
        translation 0.057000000180280314 -2.82847215720784e-06 -8.016077007756824e-10
        rotation -6.615671341501174e-09 -6.610838441091528e-09 -0.9999999999999999 1.5700000023922984
        children [
          DEF wheel Shape {
            appearance PBRAppearance {
              baseColor 0 1 0
              roughness 1
              metalness 0
            }
            geometry Cylinder {
              height 0.025
              radius 0.03
            }
          }
        ]
        boundingObject USE wheel
        physics Physics {
        }
        linearVelocity -2.7748365212860705e-06 1.6326573015591822e-06 -3.3735569382513456e-06
        angularVelocity -0.00013189226426954363 -1.0340372767344734e-06 0.000110527680851894
      }
    }
    DEF jointRight HingeJoint {
      jointParameters HingeJointParameters {
        position 5.1326866807067614e-08
        anchor -0.057 0 0
      }
      device [
        RotationalMotor {
          name "motorRight"
        }
      ]
      endPoint Solid {
        translation -0.056999999866820555 -2.8053489028326162e-06 -7.095276613992517e-10
        rotation 2.4677686190341982e-08 -2.4658113780325153e-08 0.9999999999999993 1.570000002332662
        children [
          DEF wheel Shape {
            appearance PBRAppearance {
              baseColor 0 1 0
              roughness 1
              metalness 0
            }
            geometry Cylinder {
              height 0.025
              radius 0.03
            }
          }
        ]
        name "solid(1)"
        boundingObject USE wheel
        physics Physics {
        }
        linearVelocity -2.5334917159190715e-06 1.1977868883282408e-06 -3.111195668837482e-06
        angularVelocity -0.00013189970068968321 -1.034184560126221e-06 0.00011053463215441793
      }
    }
    DEF calsterLeft Solid {
      translation 0.05438634229854031 0.004942178825045149 0.08382267705798813
      rotation 0.9995532623825744 0.029645817290531496 -0.0037948883421049587 -0.25207019092139604
      children [
        DEF caster Shape {
          appearance PBRAppearance {
            baseColor 1 0 0
            roughness 1
            metalness 0
          }
          geometry Sphere {
            radius 0.01375
          }
        }
      ]
      name "solid(2)"
      boundingObject USE caster
      physics Physics {
      }
      linearVelocity 0 2.7571968656099857e-06 0
    }
    DEF calsterRight Solid {
      translation -0.055610552463044 0.004737448114106854 0.08302191364741218
      rotation -0.12839980025905906 0.12090626198141247 0.9843247264531738 1.5867604272660474
      children [
        DEF caster Shape {
          appearance PBRAppearance {
            baseColor 1 0 0
            roughness 1
            metalness 0
          }
          geometry Sphere {
            radius 0.01375
          }
        }
      ]
      name "solid(3)"
      boundingObject USE caster
      physics Physics {
      }
      linearVelocity 0 2.7724693903951954e-06 0
    }
  ]
  boundingObject USE basePlate
  physics Physics {
  }
  controller "arm"
  linearVelocity -3.1833760481581803e-06 1.0542205793078945e-05 -3.7376479685587833e-06
  angularVelocity -0.0001318821314522217 -1.0349511793555115e-06 0.00011051620716641449
}
DEF Cylinder Solid {
  translation -1.10794 0.0250105 -0.0489232
  rotation -0.3779979942442246 0.6547109900307159 -0.6545769900327562 -2.418935307179586
  children [
    DEF Cylinder Shape {
      appearance PBRAppearance {
        baseColor 1 1 0
        roughness 1
        metalness 0
      }
      geometry Cylinder {
        height 0.05
        radius 0.025
      }
    }
  ]
  name "solid(5)"
}
DEF Testing Robot {
  translation -0.26006083926897794 0.03485096848804702 0.4299995442951996
  rotation 0.0008202247762884927 -0.9999993168215179 0.0008328191962991913 1.5708016633932285
  children [
    DEF stand Solid {
      translation -0.0025 0.02 0.07
      rotation 1 0 0 0
      children [
        DEF stand Shape {
          appearance PBRAppearance {
            baseColor 1 1 0
            roughness 1
            metalness 0
          }
          geometry Box {
            size 0.11 0.03 0.02
          }
        }
      ]
      name "solid(5)"
      boundingObject USE stand
      physics Physics {
      }
    }
    SliderJoint {
      jointParameters JointParameters {
      }
      device [
        LinearMotor {
        }
        PositionSensor {
        }
      ]
    }
    DEF handle HingeJoint {
      jointParameters HingeJointParameters {
        position -5.4401865786840946e-08
        anchor -0.0625 0.03 0.115
      }
      device [
        DEF lefthandle_position PositionSensor {
        }
        DEF lefthandle_motor RotationalMotor {
        }
      ]
      endPoint DEF handle Solid {
        translation -0.0625 0.03 0.115
        rotation -0.9999999999999999 0 0 1.5700000522295727
        scale 0.001 0.001 0.001
        children [
          Solid {
            children [
              DEF SHAPE Shape {
                appearance PBRAppearance {
                  roughness 1
                  metalness 0
                  name "DefaultMaterial"
                }
                geometry IndexedFaceSet {
                  coord Coordinate {
                    point [
                      1.22465e-16 0 5, 0 40 0, 0 0 0, 120 0 0, 120 0 5, 0 0 0, 1.22465e-16 0 5, 5 5 0, 120 0 0, 0 0 0, 5 40 0, 0 40 0, 120 40 0, 120 40 5, 120 0 0, 120 0 5, 115 5 0, 120 40 0, 5 5 5, 1.22465e-16 40 5, 1.22465e-16 0 5, 115 5 5, 120 0 5, 1.22465e-16 40 5, 115 40 5, 120 40 5, 115 5 5, 115 5 0, 5 5 0, 5 5 5, 5 40 0, 5 40 5, 5 5 0, 5 5 5, 115 40 0, 115 5 5, 115 40 0, 115 5 0, 5 40 5, 115 40 5, 1.22465e-16 40 5, 5 40 0, 0 40 0, 5 40 5, 115 40 5, 120 40 0, 115 40 0, 120 40 5
                    ]
                  }
                  normal Normal {
                    vector [
                      -1 0 2.44929e-17, -1 0 2.44929e-17, -1 0 2.44929e-17, 0 -1 0, 0 -1 0, 0 -1 0, 0 -1 0, 0 0 -1, 0 0 -1, 0 0 -1, 0 0 -1, 0 0 -1, 1 0 0, 1 0 0, 1 0 0, 1 0 0, 0 0 -1, 0 0 -1, 0 0 1, 0 0 1, 0 0 1, 0 0 1, 0 0 1, -1 0 2.44929e-17, 0 0 1, 0 0 1, 0 1 0, 0 1 0, 0 1 0, 0 1 0, 1 0 0, 1 0 0, 1 0 0, 1 0 0, 0 0 -1, -1 0 0, -1 0 0, -1 0 0, 0 0 1, -1 0 0, 0 1 0, 0 1 0, 0 1 0, 0 1 0, 0 1 0, 0 1 0, 0 1 0, 0 1 0
                    ]
                  }
                  coordIndex [
                    0, 1, 2, -1, 3, 4, 5, -1, 4, 6, 5, -1, 7, 8, 9, -1, 10, 7, 9, -1, 11, 10, 9, -1, 12, 13, 14, -1, 13, 15, 14, -1, 16, 17, 8, -1, 7, 16, 8, -1, 18, 19, 20, -1, 21, 18, 20, -1, 22, 21, 20, -1, 23, 1, 0, -1, 24, 21, 22, -1, 25, 24, 22, -1, 26, 27, 28, -1, 29, 26, 28, -1, 30, 31, 32, -1, 31, 33, 32, -1, 34, 17, 16, -1, 35, 36, 37, -1, 38, 19, 18, -1, 39, 36, 35, -1, 40, 41, 42, -1, 40, 43, 41, -1, 44, 45, 46, -1, 44, 47, 45, -1
                  ]
                }
              }
            ]
            name ""
            boundingObject USE SHAPE
            physics Physics {
            }
          }
        ]
        name "<STL_BINARY>(1)"
        boundingObject USE SHAPE
        physics Physics {
        }
        linearVelocity 2.628652709021091e-10 -2.153573599817268e-09 -2.258338362502373e-11
        angularVelocity 5.5505800469093456e-11 -2.4363181066811845e-10 -1.0148426902218978e-07
      }
    }
    Display {
      children [
        Shape {
          appearance Appearance {
            material Material {
              emissiveColor 1 1 1
            }
            texture ImageTexture {
              filtering 0
            }
          }
        }
      ]
      width 128
      height 128
    }
    DEF body Shape {
      appearance PBRAppearance {
        baseColor 0 0 1
        roughness 1
        metalness 0
      }
      geometry Box {
        size 0.14 0.01 0.18
      }
    }
    DEF left HingeJoint {
      jointParameters HingeJointParameters {
        position 2.0693914539625046e-10
        anchor 0.075 0 -0.03
      }
      device [
        DEF left_motor RotationalMotor {
          name "left_motor"
        }
        DEF left_encoder PositionSensor {
          name "left_encoder"
        }
      ]
      endPoint Solid {
        translation 0.075 0 -0.03
        rotation 0.004612023834456952 -0.004613591283575594 -0.999978721779428 4.712165185348286
        children [
          DEF wheel Shape {
            appearance PBRAppearance {
              baseColor 0 1 0
              roughness 1
              metalness 0
            }
            geometry Cylinder {
              height 0.01
              radius 0.035
            }
          }
        ]
        boundingObject USE wheel
        physics Physics {
        }
        linearVelocity -2.513752376073456e-11 1.0353157706785477e-08 2.8591088822881176e-12
        angularVelocity -1.3210260093422399e-11 -2.4232932683602583e-10 8.468533587925003e-10
      }
    }
    DEF right HingeJoint {
      jointParameters HingeJointParameters {
        position -7.150858281956964e-11
        anchor -0.075 0 -0.03
      }
      device [
        DEF right_encoder PositionSensor {
          name "right_encoder"
        }
        DEF right_motor RotationalMotor {
          name "right_motor"
        }
      ]
      endPoint Solid {
        translation -0.0750001 0 -0.03
        rotation 3.297572902630921e-06 -3.2992814642335253e-06 0.9999999999891204 1.571000057517557
        children [
          DEF wheel Shape {
            appearance PBRAppearance {
              baseColor 0 1 0
              roughness 1
              metalness 0
            }
            geometry Cylinder {
              height 0.01
              radius 0.035
            }
          }
        ]
        name "solid(1)"
        boundingObject USE wheel
        physics Physics {
        }
        linearVelocity 3.181493464195797e-11 1.0637580682889198e-08 2.856181398763111e-12
        angularVelocity -1.3201131725021352e-11 -2.423532711218308e-10 -1.0378814699894163e-09
      }
    }
    DEF casterSolid Solid {
      translation 0 -0.02 0.07
      children [
        DEF caster Shape {
          appearance PBRAppearance {
            baseColor 0 1 0
            roughness 1
            metalness 0
          }
          geometry Sphere {
            radius 0.015
            subdivision 2
          }
        }
      ]
      name "solid(2)"
      boundingObject USE caster
      physics Physics {
      }
    }
    Camera {
      translation 0 0.05 0.09
      rotation 0.00010394198776057495 -0.9914448832549232 -0.13052598463024384 -3.140015307179586
      children [
        Shape {
          appearance PBRAppearance {
            roughness 1
            metalness 0
          }
          geometry Cylinder {
            height 0.01
            radius 0.005
          }
        }
      ]
      name "cam"
      width 128
      height 128
    }
  ]
  name "PlexCV"
  boundingObject USE body
  physics Physics {
  }
  controller ""
  linearVelocity 3.7186834808244005e-12 -4.023391105099717e-12 -9.588806596195968e-13
  angularVelocity -1.4185413215555306e-11 -2.4235408807357423e-10 -9.356429037408864e-11
}
DEF Box Solid {
  translation -0.9599999999691518 0.024950950000000003 -0.3399999999691514
  rotation 0.9745591628407944 0.14354069807307326 0.17213513911966086 -2.9015890595332305e-17
  children [
    DEF Box Shape {
      appearance PBRAppearance {
        baseColor 1 1 0
        roughness 1
        metalness 0
      }
      geometry Box {
        size 0.05 0.05 0.05
      }
    }
  ]
  boundingObject USE Box
  physics Physics {
  }
  linearVelocity -2.368166367016885e-17 0 1.6075323964459314e-17
  angularVelocity 5.32907051820075e-16 -1.574358463737119e-16 1.0658141036401504e-15
}
DEF Cyan Solid {
  translation -0.8 -0.049 -0.2
  children [
    Shape {
      appearance PBRAppearance {
        baseColor 0 1 1
        roughness 1
        metalness 0
      }
      geometry Box {
        size 0.9 0.1 0.92
      }
    }
  ]
  name "solid(1)"
}
DEF Black Solid {
  translation -0.8 -0.049 0.72
  children [
    Shape {
      appearance PBRAppearance {
        baseColor 0 0 0
        roughness 1
        metalness 0
      }
      geometry Box {
        size 0.9 0.1 0.92
      }
    }
  ]
  name "solid(2)"
}
DEF Magenta Solid {
  translation -0.05 -0.049 -0.2
  children [
    Shape {
      appearance PBRAppearance {
        baseColor 1 0 1
        roughness 1
        metalness 0
      }
      geometry Box {
        size 0.6 0.1 0.92
      }
    }
  ]
  name "solid(3)"
}
DEF Yellow Solid {
  translation -0.05 -0.049 0.72
  children [
    Shape {
      appearance PBRAppearance {
        baseColor 1 1 0
        roughness 1
        metalness 0
      }
      geometry Box {
        size 0.6 0.1 0.92
      }
    }
  ]
  name "solid(4)"
}
DEF Mosaic_wall Solid {
  translation -1.26 0 -0.67
  scale 0.001 0.001 0.001
  children [
    Solid {
      children [
        DEF Mosaic_wall Shape {
          appearance PBRAppearance {
            baseColor 0 0 0
            roughness 1
            metalness 0
            name "DefaultMaterial"
          }
          geometry IndexedFaceSet {
            coord Coordinate {
              point [
                1510 0 1850, 910 0 1850, 1510 250 1850, 910 250 1850, 1520 250 370, 1520 250 1860, 1520 0 370, 1520 0 1860, 910 250 1860, 910 250 1850, 910 0 1860, 910 0 1850, 1520 250 1860, 910 250 1860, 1520 0 1860, 910 0 1860, 910 250 1850, 910 250 1860, 1510 250 1850, 1520 250 1860, 1510 250 370, 1520 250 370, 1510 0 370, 1520 0 370, 1510 0 1850, 1520 0 1860, 910 0 1850, 910 0 1860, 1510 250 370, 1520 250 370, 1510 0 370, 1520 0 370, 1510 250 1850, 1510 250 370, 1510 0 1850, 1510 0 370, 460 250 1850, 460 0 1850, 10 250 1850, 10 0 1850, 0 250 1860, 0 250 0, 0 0 1860, 0 0 0, 460 250 1860, 0 250 1860, 460 0 1860, 0 0 1860, 460 250 1850, 460 250 1860, 460 0 1850, 460 0 1860, 1520 250 9.99999, 1520 250 0, 10 250 9.99999, 0 250 0, 10 250 1850, 0 250 1860, 460 250 1850, 460 250 1860, 460 0 1850, 460 0 1860, 10 0 1850, 0 0 1860, 10 0 9.99999, 0 0 0, 1520 0 9.99999, 1520 0 0, 0 250 0, 1520 250 0, 0 0 0, 1520 0 0, 10 250 1850, 10 0 1850, 10 250 9.99999, 10 0 9.99999, 1520 250 0, 1520 250 9.99999, 1520 0 0, 1520 0 9.99999, 1520 250 9.99999, 10 250 9.99999, 1520 0 9.99999, 10 0 9.99999
              ]
            }
            normal Normal {
              vector [
                0 0 -1, 0 0 -1, 0 0 -1, 0 0 -1, 1 0 0, 1 0 0, 1 0 0, 1 0 0, -1 0 1.22465e-16, -1 0 1.22465e-16, -1 0 1.22465e-16, -1 0 1.22465e-16, 0 0 1, 0 0 1, 0 0 1, 0 0 1, 0 1 0, 0 1 0, 0 1 0, 0 1 0, 0 1 0, 0 1 0, 0 -1 0, 0 -1 0, 0 -1 0, 0 -1 0, 0 -1 0, 0 -1 0, 0 0 -1, 0 0 -1, 0 0 -1, 0 0 -1, -1 0 0, -1 0 0, -1 0 0, -1 0 0, 0 0 -1, 0 0 -1, 0 0 -1, 0 0 -1, -1 0 0, -1 0 0, -1 0 0, -1 0 0, 0 0 1, 0 0 1, 0 0 1, 0 0 1, 1 0 0, 1 0 0, 1 0 0, 1 0 0, 0 1 0, 0 1 0, 0 1 0, 0 1 0, 0 1 0, 0 1 0, 0 1 0, 0 1 0, 0 -1 0, 0 -1 0, 0 -1 0, 0 -1 0, 0 -1 0, 0 -1 0, 0 -1 0, 0 -1 0, 0 0 -1, 0 0 -1, 0 0 -1, 0 0 -1, 1 0 0, 1 0 0, 1 0 0, 1 0 0, 1 0 0, 1 0 0, 1 0 0, 1 0 0, 0 0 1, 0 0 1, 0 0 1, 0 0 1
              ]
            }
            coordIndex [
              0, 1, 2, -1, 2, 1, 3, -1, 4, 5, 6, -1, 6, 5, 7, -1, 8, 9, 10, -1, 10, 9, 11, -1, 12, 13, 14, -1, 14, 13, 15, -1, 16, 17, 18, -1, 18, 17, 19, -1, 18, 19, 20, -1, 20, 19, 21, -1, 22, 23, 24, -1, 24, 23, 25, -1, 24, 25, 26, -1, 26, 25, 27, -1, 28, 29, 30, -1, 30, 29, 31, -1, 32, 33, 34, -1, 34, 33, 35, -1, 36, 37, 38, -1, 38, 37, 39, -1, 40, 41, 42, -1, 42, 41, 43, -1, 44, 45, 46, -1, 46, 45, 47, -1, 48, 49, 50, -1, 50, 49, 51, -1, 52, 53, 54, -1, 54, 53, 55, -1, 54, 55, 56, -1, 56, 55, 57, -1, 56, 57, 58, -1, 58, 57, 59, -1, 60, 61, 62, -1, 62, 61, 63, -1, 62, 63, 64, -1, 64, 63, 65, -1, 64, 65, 66, -1, 66, 65, 67, -1, 68, 69, 70, -1, 70, 69, 71, -1, 72, 73, 74, -1, 74, 73, 75, -1, 76, 77, 78, -1, 78, 77, 79, -1, 80, 81, 82, -1, 82, 81, 83, -1
            ]
          }
        }
      ]
      name ""
    }
  ]
  name "<STL_BINARY>"
  boundingObject USE Mosaic_wall
}
Solid {
  translation -0.23529899971206206 0.030958447670547 -0.03613483607848704
  rotation 0.5793898984863765 0.5793898984870409 -0.5732492399149981 -2.1005575701329926
  scale 6.19436 6.19436 6.19436
  children [
    DEF ball Shape {
      appearance PBRAppearance {
        roughness 1
        metalness 0
      }
      geometry Box {
        size 0.01 0.01 0.01
      }
    }
  ]
  name "solid(6)"
  boundingObject USE ball
  physics Physics {
  }
  linearVelocity 2.285640864272424e-15 1.1306822583604729e-12 -2.7800497919234837e-13
  angularVelocity -8.969591767467425e-12 -1.102090229257757e-15 -6.75807121994719e-14
}
