#VRML_SIM R2021a utf8
WorldInfo {
  coordinateSystem "NUE"
}
Viewpoint {
  orientation -0.6421713302849261 -0.735639331227709 -0.21552437660491514 0.8560396746346255
  position -0.19376836853892934 0.1448484281090005 0.7705404700630692
}
TexturedBackground {
}
TexturedBackgroundLight {
}
RectangleArena {
  floorSize 5 5
  floorAppearance Parquetry {
    type "dark strip"
    colorOverride 0 0 0
  }
}
DEF Cylinder Solid {
  translation -1.10794 0.0250105 -0.0489232
  rotation -0.3779979942442246 0.6547109900307159 -0.6545769900327562 -2.418935307179586
  children [
    DEF Cylinder Shape {
      appearance PBRAppearance {
        baseColor 1 1 0
        roughness 1
        metalness 0
      }
      geometry Cylinder {
        height 0.05
        radius 0.025
      }
    }
  ]
  name "solid(5)"
}
DEF Box Solid {
  translation -0.894024 0.025 -0.193284
  rotation 0 1 0 1.57079
  children [
    DEF Box Shape {
      appearance PBRAppearance {
        baseColor 1 1 0
        roughness 1
        metalness 0
      }
      geometry Box {
        size 0.05 0.05 0.05
      }
    }
  ]
  boundingObject USE Box
  physics Physics {
  }
}
DEF Cyan Solid {
  translation -0.8 -0.049 -0.2
  children [
    Shape {
      appearance PBRAppearance {
        baseColor 0 1 1
        roughness 1
        metalness 0
      }
      geometry Box {
        size 0.9 0.1 0.92
      }
    }
  ]
  name "solid(1)"
}
DEF Black Solid {
  translation -0.8 -0.049 0.72
  children [
    Shape {
      appearance PBRAppearance {
        baseColor 0 0 0
        roughness 1
        metalness 0
      }
      geometry Box {
        size 0.9 0.1 0.92
      }
    }
  ]
  name "solid(2)"
}
DEF Magenta Solid {
  translation -0.05 -0.049 -0.2
  children [
    Shape {
      appearance PBRAppearance {
        baseColor 1 0 1
        roughness 1
        metalness 0
      }
      geometry Box {
        size 0.6 0.1 0.92
      }
    }
  ]
  name "solid(3)"
}
DEF Yellow Solid {
  translation -0.05 -0.049 0.72
  children [
    Shape {
      appearance PBRAppearance {
        baseColor 1 1 0
        roughness 1
        metalness 0
      }
      geometry Box {
        size 0.6 0.1 0.92
      }
    }
  ]
  name "solid(4)"
}
DEF Mosaic_wall Solid {
  translation -1.26 0 -0.67
  scale 0.001 0.001 0.001
  children [
    Solid {
      children [
        DEF Mosaic_wall Shape {
          appearance PBRAppearance {
            baseColor 0 0 0
            roughness 1
            metalness 0
            name "DefaultMaterial"
          }
          geometry IndexedFaceSet {
            coord Coordinate {
              point [
                1510 0 1850, 910 0 1850, 1510 250 1850, 910 250 1850, 1520 250 370, 1520 250 1860, 1520 0 370, 1520 0 1860, 910 250 1860, 910 250 1850, 910 0 1860, 910 0 1850, 1520 250 1860, 910 250 1860, 1520 0 1860, 910 0 1860, 910 250 1850, 910 250 1860, 1510 250 1850, 1520 250 1860, 1510 250 370, 1520 250 370, 1510 0 370, 1520 0 370, 1510 0 1850, 1520 0 1860, 910 0 1850, 910 0 1860, 1510 250 370, 1520 250 370, 1510 0 370, 1520 0 370, 1510 250 1850, 1510 250 370, 1510 0 1850, 1510 0 370, 460 250 1850, 460 0 1850, 10 250 1850, 10 0 1850, 0 250 1860, 0 250 0, 0 0 1860, 0 0 0, 460 250 1860, 0 250 1860, 460 0 1860, 0 0 1860, 460 250 1850, 460 250 1860, 460 0 1850, 460 0 1860, 1520 250 9.99999, 1520 250 0, 10 250 9.99999, 0 250 0, 10 250 1850, 0 250 1860, 460 250 1850, 460 250 1860, 460 0 1850, 460 0 1860, 10 0 1850, 0 0 1860, 10 0 9.99999, 0 0 0, 1520 0 9.99999, 1520 0 0, 0 250 0, 1520 250 0, 0 0 0, 1520 0 0, 10 250 1850, 10 0 1850, 10 250 9.99999, 10 0 9.99999, 1520 250 0, 1520 250 9.99999, 1520 0 0, 1520 0 9.99999, 1520 250 9.99999, 10 250 9.99999, 1520 0 9.99999, 10 0 9.99999
              ]
            }
            normal Normal {
              vector [
                0 0 -1, 0 0 -1, 0 0 -1, 0 0 -1, 1 0 0, 1 0 0, 1 0 0, 1 0 0, -1 0 1.22465e-16, -1 0 1.22465e-16, -1 0 1.22465e-16, -1 0 1.22465e-16, 0 0 1, 0 0 1, 0 0 1, 0 0 1, 0 1 0, 0 1 0, 0 1 0, 0 1 0, 0 1 0, 0 1 0, 0 -1 0, 0 -1 0, 0 -1 0, 0 -1 0, 0 -1 0, 0 -1 0, 0 0 -1, 0 0 -1, 0 0 -1, 0 0 -1, -1 0 0, -1 0 0, -1 0 0, -1 0 0, 0 0 -1, 0 0 -1, 0 0 -1, 0 0 -1, -1 0 0, -1 0 0, -1 0 0, -1 0 0, 0 0 1, 0 0 1, 0 0 1, 0 0 1, 1 0 0, 1 0 0, 1 0 0, 1 0 0, 0 1 0, 0 1 0, 0 1 0, 0 1 0, 0 1 0, 0 1 0, 0 1 0, 0 1 0, 0 -1 0, 0 -1 0, 0 -1 0, 0 -1 0, 0 -1 0, 0 -1 0, 0 -1 0, 0 -1 0, 0 0 -1, 0 0 -1, 0 0 -1, 0 0 -1, 1 0 0, 1 0 0, 1 0 0, 1 0 0, 1 0 0, 1 0 0, 1 0 0, 1 0 0, 0 0 1, 0 0 1, 0 0 1, 0 0 1
              ]
            }
            coordIndex [
              0, 1, 2, -1, 2, 1, 3, -1, 4, 5, 6, -1, 6, 5, 7, -1, 8, 9, 10, -1, 10, 9, 11, -1, 12, 13, 14, -1, 14, 13, 15, -1, 16, 17, 18, -1, 18, 17, 19, -1, 18, 19, 20, -1, 20, 19, 21, -1, 22, 23, 24, -1, 24, 23, 25, -1, 24, 25, 26, -1, 26, 25, 27, -1, 28, 29, 30, -1, 30, 29, 31, -1, 32, 33, 34, -1, 34, 33, 35, -1, 36, 37, 38, -1, 38, 37, 39, -1, 40, 41, 42, -1, 42, 41, 43, -1, 44, 45, 46, -1, 46, 45, 47, -1, 48, 49, 50, -1, 50, 49, 51, -1, 52, 53, 54, -1, 54, 53, 55, -1, 54, 55, 56, -1, 56, 55, 57, -1, 56, 57, 58, -1, 58, 57, 59, -1, 60, 61, 62, -1, 62, 61, 63, -1, 62, 63, 64, -1, 64, 63, 65, -1, 64, 65, 66, -1, 66, 65, 67, -1, 68, 69, 70, -1, 70, 69, 71, -1, 72, 73, 74, -1, 74, 73, 75, -1, 76, 77, 78, -1, 78, 77, 79, -1, 80, 81, 82, -1, 82, 81, 83, -1
            ]
          }
        }
      ]
      name ""
    }
  ]
  name "<STL_BINARY>"
  boundingObject USE Mosaic_wall
}
DEF slider_robot Robot {
  translation 0.02 0.03 0.41
  children [
    DEF handle HingeJoint {
      jointParameters HingeJointParameters {
        anchor 0 0 0.1125
      }
      device [
        RotationalMotor {
          name "handleMotor"
        }
        PositionSensor {
          name "handleEncoder"
        }
      ]
      endPoint Solid {
        translation 0 0 0.1125
        rotation 1 0 0 0
        children [
          DEF leftSlider SliderJoint {
            jointParameters JointParameters {
              axis -1 0 0
            }
            device [
              LinearMotor {
                name "leftSlider"
              }
            ]
            endPoint Solid {
              translation 0.0675 -0.01 0.0425
              children [
                DEF rightSlider Shape {
                  appearance PBRAppearance {
                    baseColor 1 0 0
                    roughness 1
                    metalness 0
                  }
                  geometry Box {
                    size 0.005 0.025 0.07
                  }
                }
              ]
              name "solid(2)"
              boundingObject USE rightSlider
              physics Physics {
              }
            }
          }
          DEF rightSlider SliderJoint {
            jointParameters JointParameters {
              axis 1 0 0
            }
            device [
              LinearMotor {
                name "rightSlider"
              }
            ]
            endPoint Solid {
              translation -0.0675 -0.01 0.0425
              children [
                DEF rightSlider Shape {
                  appearance PBRAppearance {
                    baseColor 1 0 0
                    roughness 1
                    metalness 0
                  }
                  geometry Box {
                    size 0.005 0.025 0.07
                  }
                }
              ]
              name "solid(4)"
              boundingObject USE rightSlider
              physics Physics {
              }
            }
          }
          DEF rightHandle Solid {
            translation -0.045 -0.01 0.005
            children [
              DEF leftHandle Shape {
                appearance PBRAppearance {
                  baseColor 0 0 1
                  roughness 1
                  metalness 0
                }
                geometry Box {
                  size 0.05 0.025 0.005
                }
              }
            ]
            name "solid(1)"
            boundingObject USE leftHandle
            physics Physics {
            }
          }
          DEF leftHandle Solid {
            translation 0.045 -0.01 0.005
            children [
              DEF leftHandle Shape {
                appearance PBRAppearance {
                  baseColor 0 0 1
                  roughness 1
                  metalness 0
                }
                geometry Box {
                  size 0.05 0.025 0.005
                }
              }
            ]
            name "solid(8)"
            boundingObject USE leftHandle
            physics Physics {
            }
          }
          DEF handle Shape {
            appearance PBRAppearance {
              baseColor 0 1 0
              roughness 1
              metalness 0
            }
            geometry Box {
              size 0.14 0.01 0.005
            }
          }
        ]
        name "solid(4)"
        boundingObject USE handle
        physics Physics {
        }
      }
    }
    DEF leftTouchSensor TouchSensor {
      translation 0.0645 -0.01 0.22
      children [
        DEF lefttTouchSensor Shape {
          appearance PBRAppearance {
            baseColor 0 0 0
            roughness 1
            metalness 0
          }
          geometry Box {
            size 0.001 0.01 0.065
          }
        }
      ]
      name "leftTouchSensor(1)"
      boundingObject USE lefttTouchSensor
      physics Physics {
      }
    }
    DEF rightTouchSensor TouchSensor {
      translation -0.0645 -0.01 0.23
      children [
        DEF rightTouchSensor Shape {
          appearance PBRAppearance {
            baseColor 0 0 0
            roughness 1
            metalness 0
          }
          geometry Box {
            size 0.001 0.01 0.065
          }
        }
      ]
      name "rightTouchSensor"
      boundingObject USE rightTouchSensor
      physics Physics {
      }
    }
    DEF basePlate Group {
      children [
        Transform {
          translation 0 0 0.005
          children [
            Shape {
              appearance PBRAppearance {
                baseColor 0 0 1
                roughness 1
                metalness 0
              }
              geometry Box {
                size 0.08 0.005 0.07
              }
            }
          ]
        }
        Transform {
          translation 0 0 0.075
          children [
            Shape {
              appearance PBRAppearance {
                baseColor 0 1 1
                roughness 1
                metalness 0
              }
              geometry Box {
                size 0.14 0.005 0.07
              }
            }
          ]
        }
      ]
    }
    DEF jointLeft HingeJoint {
      jointParameters HingeJointParameters {
        anchor 0.057 0 0
      }
      device [
        RotationalMotor {
          name "motorLeft"
        }
      ]
      endPoint Solid {
        translation 0.057 -1.1083861204024157e-06 0
        rotation 0 0 -1 1.57
        children [
          DEF wheel Shape {
            appearance PBRAppearance {
              baseColor 0 1 0
              roughness 1
              metalness 0
            }
            geometry Cylinder {
              height 0.025
              radius 0.03
            }
          }
        ]
        boundingObject USE wheel
        physics Physics {
        }
      }
    }
    DEF jointRight HingeJoint {
      jointParameters HingeJointParameters {
        anchor -0.057 0 0
      }
      device [
        RotationalMotor {
          name "motorRight"
        }
      ]
      endPoint Solid {
        translation -0.057 -1.1083861204024157e-06 0
        rotation 0 0 1 1.57
        children [
          DEF wheel Shape {
            appearance PBRAppearance {
              baseColor 0 1 0
              roughness 1
              metalness 0
            }
            geometry Cylinder {
              height 0.025
              radius 0.03
            }
          }
        ]
        name "solid(1)"
        boundingObject USE wheel
        physics Physics {
        }
      }
    }
    DEF calsterLeft Solid {
      translation 0.055 -0.01625 0.09
      children [
        DEF caster Shape {
          appearance PBRAppearance {
            baseColor 1 0 0
            roughness 1
            metalness 0
          }
          geometry Sphere {
            radius 0.01375
          }
        }
      ]
      name "solid(2)"
      boundingObject USE caster
      physics Physics {
      }
    }
    DEF calsterRight Solid {
      translation -0.055 -0.01625 0.09
      rotation 0 0 1 1.57
      children [
        DEF caster Shape {
          appearance PBRAppearance {
            baseColor 1 0 0
            roughness 1
            metalness 0
          }
          geometry Sphere {
            radius 0.01375
          }
        }
      ]
      name "solid(3)"
      boundingObject USE caster
      physics Physics {
      }
    }
  ]
  name "robot(1)"
  boundingObject USE basePlate
  physics Physics {
  }
  controller "arm"
}
