#VRML_SIM R2021a utf8
WorldInfo {
  coordinateSystem "NUE"
}
Viewpoint {
  orientation -0.5938205137213625 0.7363003380714676 0.32440562516630284 1.2766661436226494
  position 0.3733941721233276 0.22646502033842625 0.3110480956276901
}
TexturedBackground {
}
TexturedBackgroundLight {
}
RectangleArena {
}
DEF armBase Solid {
  translation -0.1677978503544319 0.014968437551567076 0.1595357723931726
  rotation 0.012651640174814988 0.99991984242964 -0.0004946881550284784 0.07816814002960014
  children [
    DEF armBaseShape Shape {
      appearance PBRAppearance {
        baseColor 0.666667 0 1
        roughness 1
        metalness 0
      }
      geometry Box {
        size 0.12 0.03 0.02
      }
    }
    DEF jointArm HingeJoint {
      jointParameters HingeJointParameters {
        position 2.9420580692343976
        anchor 0 0.01 0.005
      }
      endPoint Solid {
        translation -3.3403627019802618e-18 0.00987005326571831 0.004661519259571226
        rotation 1 -9.22498745232517e-17 -1.095538907718022e-18 0.5408570246560211
        children [
          DEF arm Group {
            children [
              Transform {
                translation 0 0 0.0375
                children [
                  Shape {
                    appearance PBRAppearance {
                      baseColor 1 0 1
                      roughness 1
                      metalness 0
                    }
                    geometry Box {
                      size 0.12 0.01 0.005
                    }
                  }
                ]
              }
              Transform {
                translation -0.0625 0 0.02
                children [
                  Shape {
                    appearance PBRAppearance {
                      baseColor 1 0 1
                      roughness 1
                      metalness 0
                    }
                    geometry Box {
                      size 0.005 0.01 0.04
                    }
                  }
                ]
              }
              Transform {
                translation 0.0625 0 0.02
                children [
                  Shape {
                    appearance PBRAppearance {
                      baseColor 1 0 1
                      roughness 1
                      metalness 0
                    }
                    geometry Box {
                      size 0.005 0.01 0.04
                    }
                  }
                ]
              }
            ]
          }
        ]
        boundingObject USE arm
        physics Physics {
        }
      }
    }
  ]
  name "solid(4)"
  boundingObject USE armBaseShape
  physics Physics {
  }
}
Robot {
  translation 0 0.03 0
  children [
    DEF basePlate Group {
      children [
        Transform {
          translation 0 0 0.005
          children [
            Shape {
              appearance PBRAppearance {
                baseColor 0 0 1
                roughness 1
                metalness 0
              }
              geometry Box {
                size 0.08 0.005 0.07
              }
            }
          ]
        }
        Transform {
          translation 0 0 0.075
          children [
            Shape {
              appearance PBRAppearance {
                baseColor 0 1 1
                roughness 1
                metalness 0
              }
              geometry Box {
                size 0.14 0.005 0.07
              }
            }
          ]
        }
      ]
    }
    DEF jointLeft HingeJoint {
      jointParameters HingeJointParameters {
        anchor 0.057 0 0
      }
      device [
        RotationalMotor {
          name "motorLeft"
        }
      ]
      endPoint Solid {
        translation 0.057 -1.1083861204024157e-06 0
        rotation 0 0 -1 1.57
        children [
          DEF wheel Shape {
            appearance PBRAppearance {
              baseColor 0 1 0
              roughness 1
              metalness 0
            }
            geometry Cylinder {
              height 0.025
              radius 0.03
            }
          }
        ]
        boundingObject USE wheel
        physics Physics {
        }
      }
    }
    DEF jointRight HingeJoint {
      jointParameters HingeJointParameters {
        anchor -0.057 0 0
      }
      device [
        RotationalMotor {
          name "motorRight"
        }
      ]
      endPoint Solid {
        translation -0.057 -1.1083861204024157e-06 0
        rotation 0 0 1 1.57
        children [
          DEF wheel Shape {
            appearance PBRAppearance {
              baseColor 0 1 0
              roughness 1
              metalness 0
            }
            geometry Cylinder {
              height 0.025
              radius 0.03
            }
          }
        ]
        name "solid(1)"
        boundingObject USE wheel
        physics Physics {
        }
      }
    }
    DEF calsterLeft Solid {
      translation 0.055 -0.01625 0.09
      children [
        DEF caster Shape {
          appearance PBRAppearance {
            baseColor 1 0 0
            roughness 1
            metalness 0
          }
          geometry Sphere {
            radius 0.01375
          }
        }
      ]
      name "solid(2)"
      boundingObject USE caster
      physics Physics {
      }
    }
    DEF calsterRight Solid {
      translation -0.055 -0.01625 0.09
      rotation 0 0 1 1.57
      children [
        DEF caster Shape {
          appearance PBRAppearance {
            baseColor 1 0 0
            roughness 1
            metalness 0
          }
          geometry Sphere {
            radius 0.01375
          }
        }
      ]
      name "solid(3)"
      boundingObject USE caster
      physics Physics {
      }
    }
    DEF armBase Solid {
      translation 0 0.01 0.085
      children [
        DEF armBaseShape Shape {
          appearance PBRAppearance {
            baseColor 0.666667 0 1
            roughness 1
            metalness 0
          }
          geometry Box {
            size 0.128 0.02 0.02
          }
        }
        DEF jointArm HingeJoint {
          jointParameters HingeJointParameters {
            position 2.2
            anchor 0 0.02 0
            maxStop 3
          }
          endPoint Solid {
            translation 0 0.02 0
            rotation 1 0 0 0.7000000000000002
            children [
              DEF arm Group {
                children [
                  Transform {
                    translation 0 -0.002 0.038
                    rotation 1 0 0 -0.7
                    children [
                      Shape {
                        appearance PBRAppearance {
                          baseColor 1 0 1
                          roughness 1
                          metalness 0
                        }
                        geometry Box {
                          size 0.14 0.01 0.005
                        }
                      }
                    ]
                  }
                  Transform {
                    translation -0.067 0 0.02
                    children [
                      Shape {
                        appearance PBRAppearance {
                          baseColor 1 0 1
                          roughness 1
                          metalness 0
                        }
                        geometry Box {
                          size 0.006 0.01 0.04
                        }
                      }
                    ]
                  }
                  Transform {
                    translation 0.067 0 0.02
                    children [
                      Shape {
                        appearance PBRAppearance {
                          baseColor 1 0 1
                          roughness 1
                          metalness 0
                        }
                        geometry Box {
                          size 0.006 0.01 0.04
                        }
                      }
                    ]
                  }
                ]
              }
            ]
            boundingObject USE arm
            physics Physics {
            }
          }
        }
      ]
      name "solid(4)"
      boundingObject USE armBaseShape
      physics Physics {
      }
    }
  ]
  boundingObject USE basePlate
  physics Physics {
  }
}
Robot {
  translation 0.19 0.03 0.1
  children [
    DEF basePlate Group {
      children [
        Transform {
          translation 0 0 0.005
          children [
            Shape {
              appearance PBRAppearance {
                baseColor 0 0 1
                roughness 1
                metalness 0
              }
              geometry Box {
                size 0.08 0.005 0.07
              }
            }
          ]
        }
        Transform {
          translation 0 0 0.075
          children [
            Shape {
              appearance PBRAppearance {
                baseColor 0 1 1
                roughness 1
                metalness 0
              }
              geometry Box {
                size 0.14 0.005 0.07
              }
            }
          ]
        }
      ]
    }
    DEF jointLeft HingeJoint {
      jointParameters HingeJointParameters {
        anchor 0.057 0 0
      }
      device [
        RotationalMotor {
          name "motorLeft"
        }
      ]
      endPoint Solid {
        translation 0.057 -1.1083861204024157e-06 0
        rotation 0 0 -1 1.57
        children [
          DEF wheel Shape {
            appearance PBRAppearance {
              baseColor 0 1 0
              roughness 1
              metalness 0
            }
            geometry Cylinder {
              height 0.025
              radius 0.03
            }
          }
        ]
        boundingObject USE wheel
        physics Physics {
        }
      }
    }
    DEF jointRight HingeJoint {
      jointParameters HingeJointParameters {
        anchor -0.057 0 0
      }
      device [
        RotationalMotor {
          name "motorRight"
        }
      ]
      endPoint Solid {
        translation -0.057 -1.1083861204024157e-06 0
        rotation 0 0 1 1.57
        children [
          DEF wheel Shape {
            appearance PBRAppearance {
              baseColor 0 1 0
              roughness 1
              metalness 0
            }
            geometry Cylinder {
              height 0.025
              radius 0.03
            }
          }
        ]
        name "solid(1)"
        boundingObject USE wheel
        physics Physics {
        }
      }
    }
    DEF calsterLeft Solid {
      translation 0.055 -0.01625 0.09
      children [
        DEF caster Shape {
          appearance PBRAppearance {
            baseColor 1 0 0
            roughness 1
            metalness 0
          }
          geometry Sphere {
            radius 0.01375
          }
        }
      ]
      name "solid(2)"
      boundingObject USE caster
      physics Physics {
      }
    }
    DEF calsterRight Solid {
      translation -0.055 -0.01625 0.09
      rotation 0 0 1 1.57
      children [
        DEF caster Shape {
          appearance PBRAppearance {
            baseColor 1 0 0
            roughness 1
            metalness 0
          }
          geometry Sphere {
            radius 0.01375
          }
        }
      ]
      name "solid(3)"
      boundingObject USE caster
      physics Physics {
      }
    }
    DEF armBase Solid {
      translation 0 0.01 0.085
      children [
        DEF armBaseShape Shape {
          appearance PBRAppearance {
            baseColor 0.666667 0 1
            roughness 1
            metalness 0
          }
          geometry Box {
            size 0.128 0.02 0.02
          }
        }
        DEF jointArm HingeJoint {
          jointParameters HingeJointParameters {
            anchor 0 0.02 0
            maxStop 3
          }
          endPoint Solid {
            translation 0 0.02 0
            rotation -1 0 0 1.5
            children [
              DEF handle Solid {
                translation 0 -0.03 -0.03
                rotation 1 0 0 1.5
                children [
                  Shape {
                    appearance PBRAppearance {
                      baseColor 0 1 0
                      roughness 1
                      metalness 0
                    }
                    geometry Box {
                      size 0.14 0.005 0.005
                    }
                  }
                  DEF leftHandle Solid {
                    translation 0.045 -0.01 0
                    children [
                      DEF leftHandle Shape {
                        appearance PBRAppearance {
                          baseColor 0 0 1
                          roughness 1
                          metalness 0
                        }
                        geometry Box {
                          size 0.05 0.025 0.005
                        }
                      }
                    ]
                    name "solid(8)"
                    boundingObject USE leftHandle
                    physics Physics {
                    }
                  }
                  DEF rightHandle Solid {
                    translation -0.045 -0.01 0
                    children [
                      DEF rightHandle Shape {
                        appearance PBRAppearance {
                          baseColor 0 0 1
                          roughness 1
                          metalness 0
                        }
                        geometry Box {
                          size 0.05 0.025 0.005
                        }
                      }
                    ]
                    name "solid(6)"
                    boundingObject USE rightHandle
                    physics Physics {
                    }
                  }
                  DEF leftSlider SliderJoint {
                    jointParameters JointParameters {
                      axis -1 0 0
                    }
                    device [
                      LinearMotor {
                        name "leftSlider"
                      }
                    ]
                    endPoint Solid {
                      translation 0.0675 -0.01 0.035
                      children [
                        DEF leftSlider Shape {
                          appearance PBRAppearance {
                            baseColor 1 0 0
                            roughness 1
                            metalness 0
                          }
                          geometry Box {
                            size 0.005 0.025 0.07
                          }
                        }
                      ]
                      name "solid(5)"
                      boundingObject USE leftSlider
                      physics Physics {
                      }
                    }
                  }
                  DEF rightSlider SliderJoint {
                    jointParameters JointParameters {
                    }
                    device [
                      LinearMotor {
                        name "rightSlider"
                      }
                    ]
                    endPoint Solid {
                      translation -0.0675 -0.01 0.035
                      children [
                        DEF rightSlider Shape {
                          appearance PBRAppearance {
                            baseColor 1 0 0
                            roughness 1
                            metalness 0
                          }
                          geometry Box {
                            size 0.005 0.025 0.07
                          }
                        }
                      ]
                      name "solid(4)"
                      boundingObject USE rightSlider
                      physics Physics {
                      }
                    }
                  }
                ]
                name "solid(7)"
              }
            ]
            physics Physics {
            }
          }
        }
      ]
      name "solid(4)"
      boundingObject USE armBaseShape
      physics Physics {
      }
    }
  ]
  name "robot(2)"
  boundingObject USE basePlate
  physics Physics {
  }
}
Robot {
  translation 0.38 0.03 0
  children [
    DEF handle Solid {
      translation 0 0 0.1125
      children [
        Shape {
          appearance PBRAppearance {
            baseColor 0 1 0
            roughness 1
            metalness 0
          }
          geometry Box {
            size 0.14 0.005 0.005
          }
        }
        DEF leftHandle Solid {
          translation 0.045 -0.01 0
          children [
            DEF leftHandle Shape {
              appearance PBRAppearance {
                baseColor 0 0 1
                roughness 1
                metalness 0
              }
              geometry Box {
                size 0.05 0.025 0.005
              }
            }
          ]
          name "solid(8)"
          boundingObject USE leftHandle
          physics Physics {
          }
        }
        DEF rightHandle Solid {
          translation -0.045 -0.01 0
          children [
            DEF rightHandle Shape {
              appearance PBRAppearance {
                baseColor 0 0 1
                roughness 1
                metalness 0
              }
              geometry Box {
                size 0.05 0.025 0.005
              }
            }
          ]
          name "solid(6)"
          boundingObject USE rightHandle
          physics Physics {
          }
        }
        DEF leftSlider SliderJoint {
          jointParameters JointParameters {
            axis -1 0 0
          }
          device [
            LinearMotor {
              name "leftSlider"
            }
          ]
          endPoint Solid {
            translation 0.0675 -0.01 0.035
            children [
              DEF leftSlider Shape {
                appearance PBRAppearance {
                  baseColor 1 0 0
                  roughness 1
                  metalness 0
                }
                geometry Box {
                  size 0.005 0.025 0.07
                }
              }
            ]
            name "solid(5)"
            boundingObject USE leftSlider
            physics Physics {
            }
          }
        }
        DEF rightSlider SliderJoint {
          jointParameters JointParameters {
          }
          device [
            LinearMotor {
              name "rightSlider"
            }
          ]
          endPoint Solid {
            translation -0.0675 -0.01 0.035
            children [
              DEF rightSlider Shape {
                appearance PBRAppearance {
                  baseColor 1 0 0
                  roughness 1
                  metalness 0
                }
                geometry Box {
                  size 0.005 0.025 0.07
                }
              }
            ]
            name "solid(4)"
            boundingObject USE rightSlider
            physics Physics {
            }
          }
        }
      ]
      name "solid(7)"
    }
    DEF basePlate Group {
      children [
        Transform {
          translation 0 0 0.005
          children [
            Shape {
              appearance PBRAppearance {
                baseColor 0 0 1
                roughness 1
                metalness 0
              }
              geometry Box {
                size 0.08 0.005 0.07
              }
            }
          ]
        }
        Transform {
          translation 0 0 0.075
          children [
            Shape {
              appearance PBRAppearance {
                baseColor 0 1 1
                roughness 1
                metalness 0
              }
              geometry Box {
                size 0.14 0.005 0.07
              }
            }
          ]
        }
      ]
    }
    DEF jointLeft HingeJoint {
      jointParameters HingeJointParameters {
        anchor 0.057 0 0
      }
      device [
        RotationalMotor {
          name "motorLeft"
        }
      ]
      endPoint Solid {
        translation 0.057 -1.1083861204024157e-06 0
        rotation 0 0 -1 1.57
        children [
          DEF wheel Shape {
            appearance PBRAppearance {
              baseColor 0 1 0
              roughness 1
              metalness 0
            }
            geometry Cylinder {
              height 0.025
              radius 0.03
            }
          }
        ]
        boundingObject USE wheel
        physics Physics {
        }
      }
    }
    DEF jointRight HingeJoint {
      jointParameters HingeJointParameters {
        anchor -0.057 0 0
      }
      device [
        RotationalMotor {
          name "motorRight"
        }
      ]
      endPoint Solid {
        translation -0.057 -1.1083861204024157e-06 0
        rotation 0 0 1 1.57
        children [
          DEF wheel Shape {
            appearance PBRAppearance {
              baseColor 0 1 0
              roughness 1
              metalness 0
            }
            geometry Cylinder {
              height 0.025
              radius 0.03
            }
          }
        ]
        name "solid(1)"
        boundingObject USE wheel
        physics Physics {
        }
      }
    }
    DEF calsterLeft Solid {
      translation 0.055 -0.01625 0.09
      children [
        DEF caster Shape {
          appearance PBRAppearance {
            baseColor 1 0 0
            roughness 1
            metalness 0
          }
          geometry Sphere {
            radius 0.01375
          }
        }
      ]
      name "solid(2)"
      boundingObject USE caster
      physics Physics {
      }
    }
    DEF calsterRight Solid {
      translation -0.055 -0.01625 0.09
      rotation 0 0 1 1.57
      children [
        DEF caster Shape {
          appearance PBRAppearance {
            baseColor 1 0 0
            roughness 1
            metalness 0
          }
          geometry Sphere {
            radius 0.01375
          }
        }
      ]
      name "solid(3)"
      boundingObject USE caster
      physics Physics {
      }
    }
  ]
  name "robot(1)"
  boundingObject USE basePlate
  physics Physics {
  }
  controller "arm"
}
