#VRML_SIM R2021a utf8
WorldInfo {
  coordinateSystem "NUE"
}
Viewpoint {
  orientation 0.2870718898434482 0.9418922481151457 0.17443830715272338 5.137291473843945
  position -0.37981731894675724 0.17114070654990093 0.24451995525906167
}
TexturedBackground {
}
TexturedBackgroundLight {
}
RectangleArena {
}
Robot {
  translation 0 0.03 0
  children [
    DEF basePlate Group {
      children [
        Transform {
          translation 0 0 0.005
          children [
            Shape {
              appearance PBRAppearance {
                baseColor 0 0 1
                roughness 1
                metalness 0
              }
              geometry Box {
                size 0.08 0.005 0.07
              }
            }
          ]
        }
        Transform {
          translation 0 0 0.075
          children [
            Shape {
              appearance PBRAppearance {
                baseColor 0 1 1
                roughness 1
                metalness 0
              }
              geometry Box {
                size 0.14 0.005 0.07
              }
            }
          ]
        }
      ]
    }
    DEF jointLeft HingeJoint {
      jointParameters HingeJointParameters {
        anchor 0.057 0 0
      }
      device [
        RotationalMotor {
          name "motorLeft"
        }
      ]
      endPoint Solid {
        translation 0.057 -1.1083861204024157e-06 0
        rotation 0 0 -1 1.57
        children [
          DEF wheel Shape {
            appearance PBRAppearance {
              baseColor 0 1 0
              roughness 1
              metalness 0
            }
            geometry Cylinder {
              height 0.025
              radius 0.03
            }
          }
        ]
        boundingObject USE wheel
        physics Physics {
        }
      }
    }
    DEF jointRight HingeJoint {
      jointParameters HingeJointParameters {
        anchor -0.057 0 0
      }
      device [
        RotationalMotor {
          name "motorRight"
        }
      ]
      endPoint Solid {
        translation -0.057 -1.1083861204024157e-06 0
        rotation 0 0 1 1.57
        children [
          DEF wheel Shape {
            appearance PBRAppearance {
              baseColor 0 1 0
              roughness 1
              metalness 0
            }
            geometry Cylinder {
              height 0.025
              radius 0.03
            }
          }
        ]
        name "solid(1)"
        boundingObject USE wheel
        physics Physics {
        }
      }
    }
    DEF calsterLeft Solid {
      translation 0.055 -0.01625 0.09
      children [
        DEF caster Shape {
          appearance PBRAppearance {
            baseColor 1 0 0
            roughness 1
            metalness 0
          }
          geometry Sphere {
            radius 0.01375
          }
        }
      ]
      name "solid(2)"
      boundingObject USE caster
      physics Physics {
      }
    }
    DEF calsterRight Solid {
      translation -0.055 -0.01625 0.09
      rotation 0 0 1 1.57
      children [
        DEF caster Shape {
          appearance PBRAppearance {
            baseColor 1 0 0
            roughness 1
            metalness 0
          }
          geometry Sphere {
            radius 0.01375
          }
        }
      ]
      name "solid(3)"
      boundingObject USE caster
      physics Physics {
      }
    }
  ]
  boundingObject USE basePlate
  physics Physics {
  }
}
